Workbook
Name BLDG_DELAY: CONTROL!$C$9
Name DI_DATE: CONTROL!$C$6
Name PR_DELAY: CONTROL!$C$8
Name SLP_DELAY: CONTROL!$C$10

Sheet CONTROL
A1: EPC 발전소 BOP 배관공사 공정표 — 시나리오 분석 (DI 기준)
A2: CCGT Power Plant · BOP Piping Schedule · 시나리오: Civil 선행공정 지연 → 배관공사 Impact 분석
A4: ❶ 시나리오 입력 (Scenario Inputs) | G4: ❸ 시나리오 영향 요약 (Impact Summary)
B5: 항목 (Item) | C5: 지연 (주) Delay (wk) | D5: 최대 입력 Max (wk) | E5: 설명 | G5: 계통 (System) | H5: 계통명 | I5: 최대 지연 (주) Max Delay
B6: 프로젝트 DI 기준일 (W0 Date) | C6: 2026-03-01 | D6: ← 실제 DI 날짜 입력 (Power BI 연동) | G6: CWS | H6: 냉각수 계통 | I6: =IFERROR(_xludf.MAXIFS(DATA!$N:$N,DATA!$D:$D,G6,DATA!$I:$I,"FIELD"),0) -> 0
B7: Pipe Rack Structure 지연 | C7: 0 | D7: 0~12 | E7: Rack 철골공사 지연 시 주요 배관 계통 영향 | G7: CD | H7: 복수 계통 | I7: =IFERROR(_xludf.MAXIFS(DATA!$N:$N,DATA!$D:$D,G7,DATA!$I:$I,"FIELD"),0) -> 0
B8: Building / Concrete 지연 | C8: 0 | D8: 0~12 | E8: 실내배관, 설비 기초 공사 지연 영향 | G8: FW | H8: 급수 계통 | I8: =IFERROR(_xludf.MAXIFS(DATA!$N:$N,DATA!$D:$D,G8,DATA!$I:$I,"FIELD"),0) -> 0
B9: Sleeper / Embed 지연 | C9: 0 | D9: 0~8 | E9: Support 매립물 지연 → Support 설치 지연 | G9: AUX | H9: 보조증기 계통 | I9: =IFERROR(_xludf.MAXIFS(DATA!$N:$N,DATA!$D:$D,G9,DATA!$I:$I,"FIELD"),0) -> 0
G10: NG | H10: 천연가스 계통 | I10: =IFERROR(_xludf.MAXIFS(DATA!$N:$N,DATA!$D:$D,G10,DATA!$I:$I,"FIELD"),0) -> 0
A11: ❷ 사용 방법 (Usage Guide) | G11: FO | H11: 연료유 계통 | I11: =IFERROR(_xludf.MAXIFS(DATA!$N:$N,DATA!$D:$D,G11,DATA!$I:$I,"FIELD"),0) -> 0
B12: ① C8~C10 셀에 각 Civil 공종별 지연 주수 입력 (0 = 지연 없음) | G12: CAS | H12: 압축공기 계통 | I12: =IFERROR(_xludf.MAXIFS(DATA!$N:$N,DATA!$D:$D,G12,DATA!$I:$I,"FIELD"),0) -> 0
B13: ② DATA 시트에서 Scen_Start / Scen_End 컬럼이 자동 재계산됨 | G13: CHM | H13: 약품주입 계통 | I13: =IFERROR(_xludf.MAXIFS(DATA!$N:$N,DATA!$D:$D,G13,DATA!$I:$I,"FIELD"),0) -> 0
B14: ③ GANTT 시트에서 회색 바(Baseline) vs 컬러 바(Scenario) 비교 | G14: FPS | H14: 소화 계통 | I14: =IFERROR(_xludf.MAXIFS(DATA!$N:$N,DATA!$D:$D,G14,DATA!$I:$I,"FIELD"),0) -> 0
B15: ④ Power BI에서 DATA 시트 'tbl_BOP_Schedule' 테이블 연결 | G15: SWS | H15: 서비스/음용수 | I15: =IFERROR(_xludf.MAXIFS(DATA!$N:$N,DATA!$D:$D,G15,DATA!$I:$I,"FIELD"),0) -> 0
B16: ⑤ Power BI Gantt Custom Visual로 시나리오별 일정 인터랙티브 분석 | G16: D/V | H16: 드레인/벤트 | I16: =IFERROR(_xludf.MAXIFS(DATA!$N:$N,DATA!$D:$D,G16,DATA!$I:$I,"FIELD"),0) -> 0
A19: 범 례 (Legend)
B20: MR / 발주 | C20: 자재 입고 | D20: Spool 제작 | E20: 현장 배관 설치 | F20: Support 설치
B21: 압력 / 기밀시험 | C21: Pre-Commissioning | D21: Pipe Rack | E21: Building / Concrete | F21: Sleeper / Embed
B22: Baseline (Ghost)
A24: 📊 Power BI 연동: Excel → Data → Get Data → Excel Workbook → DATA 시트 → 'tbl_BOP_Schedule' 테이블 선택
A25: 💡 권장 Power BI Visual: Gantt Chart (Profitbase) · Bar Chart (시스템별 지연 주수) · Slicer (Phase / System / Civil_Dep)

Sheet DATA
A1: Row_ID | B1: Section | C1: Sys_No | D1: Sys_Code | E1: Sys_Name_KR | F1: Sys_Name_EN | G1: Activity | H1: Type_Name | I1: Act_Phase | J1: Civil_Dep | K1: Base_Start | L1: Base_End | M1: Duration | N1: Delay_Wk | O1: Scen_Start | P1: Scen_End | Q1: Is_Delayed | R1: Type_Code | S1: Date_Base_Start | T1: Date_Scen_Start
A2: 1 | B2: CIVIL | D2: RACK | E2: Pipe Rack | F2: Pipe Rack | G2: Pipe Rack 기초 공사 | H2: Foundation | I2: CIVIL | J2: PR | K2: -28 | L2: -20 | M2: 8 | N2: =IF(I2="PROC",0,IF(J2="PR",CONTROL!$C$8,IF(J2="BLDG",CONTROL!$C$9,IF(J2="SLP",CONTROL!$C$10,0)))) -> 0 | O2: =K2+N2 -> -28 | P2: =L2+N2 -> -20 | Q2: =IF(N2>0,"DELAYED","ON TIME") -> ON TIME | R2: 8 | S2: =CONTROL!$C$6+K2*7 -> 45886 | T2: =CONTROL!$C$6+O2*7 -> 45886
A3: 2 | B3: CIVIL | D3: RACK | E3: Pipe Rack | F3: Pipe Rack | G3: Pipe Rack 철골 제작 | H3: Fabrication | I3: CIVIL | J3: PR | K3: -24 | L3: -12 | M3: 12 | N3: =IF(I3="PROC",0,IF(J3="PR",CONTROL!$C$8,IF(J3="BLDG",CONTROL!$C$9,IF(J3="SLP",CONTROL!$C$10,0)))) -> 0 | O3: =K3+N3 -> -24 | P3: =L3+N3 -> -12 | Q3: =IF(N3>0,"DELAYED","ON TIME") -> ON TIME | R3: 8 | S3: =CONTROL!$C$6+K3*7 -> 45914 | T3: =CONTROL!$C$6+O3*7 -> 45914
A4: 3 | B4: CIVIL | D4: RACK | E4: Pipe Rack | F4: Pipe Rack | G4: Pipe Rack 철골 설치 | H4: Erection | I4: CIVIL | J4: PR | K4: -14 | L4: -6 | M4: 8 | N4: =IF(I4="PROC",0,IF(J4="PR",CONTROL!$C$8,IF(J4="BLDG",CONTROL!$C$9,IF(J4="SLP",CONTROL!$C$10,0)))) -> 0 | O4: =K4+N4 -> -14 | P4: =L4+N4 -> -6 | Q4: =IF(N4>0,"DELAYED","ON TIME") -> ON TIME | R4: 8 | S4: =CONTROL!$C$6+K4*7 -> 45984 | T4: =CONTROL!$C$6+O4*7 -> 45984
A5: 4 | B5: CIVIL | D5: RACK | E5: Pipe Rack | F5: Pipe Rack | G5: Grating / Floor 설치 | H5: Grating | I5: CIVIL | J5: PR | K5: -6 | L5: -2 | M5: 4 | N5: =IF(I5="PROC",0,IF(J5="PR",CONTROL!$C$8,IF(J5="BLDG",CONTROL!$C$9,IF(J5="SLP",CONTROL!$C$10,0)))) -> 0 | O5: =K5+N5 -> -6 | P5: =L5+N5 -> -2 | Q5: =IF(N5>0,"DELAYED","ON TIME") -> ON TIME | R5: 8 | S5: =CONTROL!$C$6+K5*7 -> 46040 | T5: =CONTROL!$C$6+O5*7 -> 46040
A6: 5 | B6: CIVIL | D6: BLDG | E6: Building | F6: Building | G6: 터파기 / 철근 배근 | H6: Foundation | I6: CIVIL | J6: BLDG | K6: -28 | L6: -22 | M6: 6 | N6: =IF(I6="PROC",0,IF(J6="PR",CONTROL!$C$8,IF(J6="BLDG",CONTROL!$C$9,IF(J6="SLP",CONTROL!$C$10,0)))) -> 0 | O6: =K6+N6 -> -28 | P6: =L6+N6 -> -22 | Q6: =IF(N6>0,"DELAYED","ON TIME") -> ON TIME | R6: 9 | S6: =CONTROL!$C$6+K6*7 -> 45886 | T6: =CONTROL!$C$6+O6*7 -> 45886
A7: 6 | B7: CIVIL | D7: BLDG | E7: Building | F7: Building | G7: 콘크리트 타설 (양생) | H7: Concrete | I7: CIVIL | J7: BLDG | K7: -22 | L7: -14 | M7: 8 | N7: =IF(I7="PROC",0,IF(J7="PR",CONTROL!$C$8,IF(J7="BLDG",CONTROL!$C$9,IF(J7="SLP",CONTROL!$C$10,0)))) -> 0 | O7: =K7+N7 -> -22 | P7: =L7+N7 -> -14 | Q7: =IF(N7>0,"DELAYED","ON TIME") -> ON TIME | R7: 9 | S7: =CONTROL!$C$6+K7*7 -> 45928 | T7: =CONTROL!$C$6+O7*7 -> 45928
A8: 7 | B8: CIVIL | D8: BLDG | E8: Building | F8: Building | G8: 내부 구조물 / 지붕 공사 | H8: Structure | I8: CIVIL | J8: BLDG | K8: -14 | L8: -6 | M8: 8 | N8: =IF(I8="PROC",0,IF(J8="PR",CONTROL!$C$8,IF(J8="BLDG",CONTROL!$C$9,IF(J8="SLP",CONTROL!$C$10,0)))) -> 0 | O8: =K8+N8 -> -14 | P8: =L8+N8 -> -6 | Q8: =IF(N8>0,"DELAYED","ON TIME") -> ON TIME | R8: 9 | S8: =CONTROL!$C$6+K8*7 -> 45984 | T8: =CONTROL!$C$6+O8*7 -> 45984
A9: 8 | B9: CIVIL | D9: SLP | E9: Sleeper | F9: Sleeper | G9: Support Embed (지하/매립) | H9: Embed | I9: CIVIL | J9: SLP | K9: -18 | L9: -14 | M9: 4 | N9: =IF(I9="PROC",0,IF(J9="PR",CONTROL!$C$8,IF(J9="BLDG",CONTROL!$C$9,IF(J9="SLP",CONTROL!$C$10,0)))) -> 0 | O9: =K9+N9 -> -18 | P9: =L9+N9 -> -14 | Q9: =IF(N9>0,"DELAYED","ON TIME") -> ON TIME | R9: 10 | S9: =CONTROL!$C$6+K9*7 -> 45956 | T9: =CONTROL!$C$6+O9*7 -> 45956
A10: 9 | B10: CIVIL | D10: SLP | E10: Sleeper | F10: Sleeper | G10: Pipe Sleeper 설치 (지상) | H10: Sleeper | I10: CIVIL | J10: SLP | K10: -10 | L10: -6 | M10: 4 | N10: =IF(I10="PROC",0,IF(J10="PR",CONTROL!$C$8,IF(J10="BLDG",CONTROL!$C$9,IF(J10="SLP",CONTROL!$C$10,0)))) -> 0 | O10: =K10+N10 -> -10 | P10: =L10+N10 -> -6 | Q10: =IF(N10>0,"DELAYED","ON TIME") -> ON TIME | R10: 10 | S10: =CONTROL!$C$6+K10*7 -> 46012 | T10: =CONTROL!$C$6+O10*7 -> 46012
A11: 10 | B11: CIVIL | D11: SLP | E11: Sleeper | F11: Sleeper | G11: Anchor Bolt / Clip 확인 | H11: AnchorChk | I11: CIVIL | J11: SLP | K11: -4 | L11: -2 | M11: 2 | N11: =IF(I11="PROC",0,IF(J11="PR",CONTROL!$C$8,IF(J11="BLDG",CONTROL!$C$9,IF(J11="SLP",CONTROL!$C$10,0)))) -> 0 | O11: =K11+N11 -> -4 | P11: =L11+N11 -> -2 | Q11: =IF(N11>0,"DELAYED","ON TIME") -> ON TIME | R11: 10 | S11: =CONTROL!$C$6+K11*7 -> 46054 | T11: =CONTROL!$C$6+O11*7 -> 46054
A12: 11 | B12: PIPING | C12: 1 | D12: CWS | E12: 냉각수 계통 | F12: Cooling Water | G12: MR 발행 / 자재 발주 | H12: MR | I12: PROC | J12: NONE | K12: -16 | L12: -6 | M12: 10 | N12: =IF(I12="PROC",0,IF(J12="PR",CONTROL!$C$8,IF(J12="BLDG",CONTROL!$C$9,IF(J12="SLP",CONTROL!$C$10,0)))) -> 0 | O12: =K12+N12 -> -16 | P12: =L12+N12 -> -6 | Q12: =IF(N12>0,"DELAYED","ON TIME") -> ON TIME | R12: 1 | S12: =CONTROL!$C$6+K12*7 -> 45970 | T12: =CONTROL!$C$6+O12*7 -> 45970
A13: 12 | B13: PIPING | C13: 1 | D13: CWS | E13: 냉각수 계통 | F13: Cooling Water | G13: 자재 입고 | H13: Delivery | I13: PROC | J13: NONE | K13: -6 | L13: 2 | M13: 8 | N13: =IF(I13="PROC",0,IF(J13="PR",CONTROL!$C$8,IF(J13="BLDG",CONTROL!$C$9,IF(J13="SLP",CONTROL!$C$10,0)))) -> 0 | O13: =K13+N13 -> -6 | P13: =L13+N13 -> 2 | Q13: =IF(N13>0,"DELAYED","ON TIME") -> ON TIME | R13: 2 | S13: =CONTROL!$C$6+K13*7 -> 46040 | T13: =CONTROL!$C$6+O13*7 -> 46040
A14: 13 | B14: PIPING | C14: 1 | D14: CWS | E14: 냉각수 계통 | F14: Cooling Water | G14: Spool 제작 | H14: Fab | I14: PROC | J14: NONE | K14: 0 | L14: 6 | M14: 6 | N14: =IF(I14="PROC",0,IF(J14="PR",CONTROL!$C$8,IF(J14="BLDG",CONTROL!$C$9,IF(J14="SLP",CONTROL!$C$10,0)))) -> 0 | O14: =K14+N14 -> 0 | P14: =L14+N14 -> 6 | Q14: =IF(N14>0,"DELAYED","ON TIME") -> ON TIME | R14: 3 | S14: =CONTROL!$C$6+K14*7 -> 46082 | T14: =CONTROL!$C$6+O14*7 -> 46082
A15: 14 | B15: PIPING | C15: 1 | D15: CWS | E15: 냉각수 계통 | F15: Cooling Water | G15: 현장 배관 설치 | H15: Install | I15: FIELD | J15: PR | K15: 4 | L15: 14 | M15: 10 | N15: =IF(I15="PROC",0,IF(J15="PR",CONTROL!$C$8,IF(J15="BLDG",CONTROL!$C$9,IF(J15="SLP",CONTROL!$C$10,0)))) -> 0 | O15: =K15+N15 -> 4 | P15: =L15+N15 -> 14 | Q15: =IF(N15>0,"DELAYED","ON TIME") -> ON TIME | R15: 4 | S15: =CONTROL!$C$6+K15*7 -> 46110 | T15: =CONTROL!$C$6+O15*7 -> 46110
A16: 15 | B16: PIPING | C16: 1 | D16: CWS | E16: 냉각수 계통 | F16: Cooling Water | G16: Support 최종 설치/정렬 | H16: Support | I16: FIELD | J16: SLP | K16: 14 | L16: 16 | M16: 2 | N16: =IF(I16="PROC",0,IF(J16="PR",CONTROL!$C$8,IF(J16="BLDG",CONTROL!$C$9,IF(J16="SLP",CONTROL!$C$10,0)))) -> 0 | O16: =K16+N16 -> 14 | P16: =L16+N16 -> 16 | Q16: =IF(N16>0,"DELAYED","ON TIME") -> ON TIME | R16: 5 | S16: =CONTROL!$C$6+K16*7 -> 46180 | T16: =CONTROL!$C$6+O16*7 -> 46180
A17: 16 | B17: PIPING | C17: 1 | D17: CWS | E17: 냉각수 계통 | F17: Cooling Water | G17: 수압시험 (Hydro Test) | H17: Test | I17: FIELD | J17: PR | K17: 16 | L17: 18 | M17: 2 | N17: =IF(I17="PROC",0,IF(J17="PR",CONTROL!$C$8,IF(J17="BLDG",CONTROL!$C$9,IF(J17="SLP",CONTROL!$C$10,0)))) -> 0 | O17: =K17+N17 -> 16 | P17: =L17+N17 -> 18 | Q17: =IF(N17>0,"DELAYED","ON TIME") -> ON TIME | R17: 6 | S17: =CONTROL!$C$6+K17*7 -> 46194 | T17: =CONTROL!$C$6+O17*7 -> 46194
A18: 17 | B18: PIPING | C18: 1 | D18: CWS | E18: 냉각수 계통 | F18: Cooling Water | G18: Pre-Commissioning | H18: PreComm | I18: FIELD | J18: PR | K18: 18 | L18: 20 | M18: 2 | N18: =IF(I18="PROC",0,IF(J18="PR",CONTROL!$C$8,IF(J18="BLDG",CONTROL!$C$9,IF(J18="SLP",CONTROL!$C$10,0)))) -> 0 | O18: =K18+N18 -> 18 | P18: =L18+N18 -> 20 | Q18: =IF(N18>0,"DELAYED","ON TIME") -> ON TIME | R18: 7 | S18: =CONTROL!$C$6+K18*7 -> 46208 | T18: =CONTROL!$C$6+O18*7 -> 46208
A19: 18 | B19: PIPING | C19: 2 | D19: CD | E19: 복수 계통 | F19: Condensate | G19: MR 발행 / 자재 발주 | H19: MR | I19: PROC | J19: NONE | K19: -14 | L19: -6 | M19: 8 | N19: =IF(I19="PROC",0,IF(J19="PR",CONTROL!$C$8,IF(J19="BLDG",CONTROL!$C$9,IF(J19="SLP",CONTROL!$C$10,0)))) -> 0 | O19: =K19+N19 -> -14 | P19: =L19+N19 -> -6 | Q19: =IF(N19>0,"DELAYED","ON TIME") -> ON TIME | R19: 1 | S19: =CONTROL!$C$6+K19*7 -> 45984 | T19: =CONTROL!$C$6+O19*7 -> 45984
A20: 19 | B20: PIPING | C20: 2 | D20: CD | E20: 복수 계통 | F20: Condensate | G20: 자재 입고 | H20: Delivery | I20: PROC | J20: NONE | K20: -4 | L20: 4 | M20: 8 | N20: =IF(I20="PROC",0,IF(J20="PR",CONTROL!$C$8,IF(J20="BLDG",CONTROL!$C$9,IF(J20="SLP",CONTROL!$C$10,0)))) -> 0 | O20: =K20+N20 -> -4 | P20: =L20+N20 -> 4 | Q20: =IF(N20>0,"DELAYED","ON TIME") -> ON TIME | R20: 2 | S20: =CONTROL!$C$6+K20*7 -> 46054 | T20: =CONTROL!$C$6+O20*7 -> 46054
A21: 20 | B21: PIPING | C21: 2 | D21: CD | E21: 복수 계통 | F21: Condensate | G21: Spool 제작 | H21: Fab | I21: PROC | J21: NONE | K21: 0 | L21: 6 | M21: 6 | N21: =IF(I21="PROC",0,IF(J21="PR",CONTROL!$C$8,IF(J21="BLDG",CONTROL!$C$9,IF(J21="SLP",CONTROL!$C$10,0)))) -> 0 | O21: =K21+N21 -> 0 | P21: =L21+N21 -> 6 | Q21: =IF(N21>0,"DELAYED","ON TIME") -> ON TIME | R21: 3 | S21: =CONTROL!$C$6+K21*7 -> 46082 | T21: =CONTROL!$C$6+O21*7 -> 46082
A22: 21 | B22: PIPING | C22: 2 | D22: CD | E22: 복수 계통 | F22: Condensate | G22: 현장 배관 설치 | H22: Install | I22: FIELD | J22: BLDG | K22: 4 | L22: 12 | M22: 8 | N22: =IF(I22="PROC",0,IF(J22="PR",CONTROL!$C$8,IF(J22="BLDG",CONTROL!$C$9,IF(J22="SLP",CONTROL!$C$10,0)))) -> 0 | O22: =K22+N22 -> 4 | P22: =L22+N22 -> 12 | Q22: =IF(N22>0,"DELAYED","ON TIME") -> ON TIME | R22: 4 | S22: =CONTROL!$C$6+K22*7 -> 46110 | T22: =CONTROL!$C$6+O22*7 -> 46110
A23: 22 | B23: PIPING | C23: 2 | D23: CD | E23: 복수 계통 | F23: Condensate | G23: Support 최종 설치/정렬 | H23: Support | I23: FIELD | J23: SLP | K23: 12 | L23: 14 | M23: 2 | N23: =IF(I23="PROC",0,IF(J23="PR",CONTROL!$C$8,IF(J23="BLDG",CONTROL!$C$9,IF(J23="SLP",CONTROL!$C$10,0)))) -> 0 | O23: =K23+N23 -> 12 | P23: =L23+N23 -> 14 | Q23: =IF(N23>0,"DELAYED","ON TIME") -> ON TIME | R23: 5 | S23: =CONTROL!$C$6+K23*7 -> 46166 | T23: =CONTROL!$C$6+O23*7 -> 46166
... A86: 85 | B86: PIPING | C86: 11 | D86: D/V | E86: 드레인/벤트 | F86: Drain & Vent | G86: 수압시험 | H86: Test | I86: FIELD | J86: BLDG | K86: 12 | L86: 14 | M86: 2 | N86: =IF(I86="PROC",0,IF(J86="PR",CONTROL!$C$8,IF(J86="BLDG",CONTROL!$C$9,IF(J86="SLP",CONTROL!$C$10,0)))) -> 0 | O86: =K86+N86 -> 12 | P86: =L86+N86 -> 14 | Q86: =IF(N86>0,"DELAYED","ON TIME") -> ON TIME | R86: 6 | S86: =CONTROL!$C$6+K86*7 -> 46166 | T86: =CONTROL!$C$6+O86*7 -> 46166

Sheet GANTT
A1: BOP 배관공사 공정표 — 시나리오 비교 Gantt (회색=Baseline / 컬러=시나리오)
A2: ▣ CONTROL 시트 C8~C10 값 변경 시 자동 반영 | W0 = DI 기준일 | 회색 바: 원래 계획 (Baseline) | 컬러 바: 시나리오 반영 일정 | 적색 연장: 지연 구간
A3: 범 례 | E3: MR / 발주 | G3: 자재 입고 | I3: Spool 제작 | K3: 현장 배관 설치 | M3: Support 설치 | O3: 압력 / 기밀시험 | Q3: Pre-Commissioning | S3: Pipe Rack | U3: Building / Concrete | W3: Sleeper / Embed | Y3: Baseline (Ghost)
A4: ID | B4: 섹션 | C4: 계통 | D4: 작업 항목 | E4: Phase | F4: 기간 | G4: B.Start | H4: B.End | I4: S.Start | J4: S.End | K4: 지연(주) | L4: Type | M4: W-32 | N4: W-30 | O4: W-28 | P4: W-26 | Q4: W-24 | R4: W-22 | S4: W-20 | T4: W-18 | U4: W-16 | V4: W-14 | W4: W-12 | X4: W-10 | Y4: W-8 | Z4: W-6 | AA4: W-4 | AB4: W-2 | AC4: W0 ▼DI | AD4: W+2 | AE4: W+4 | AF4: W+6 | AG4: W+8 | AH4: W+10 | AI4: W+12 | AJ4: W+14 | AK4: W+16 | AL4: W+18 | AM4: W+20 | AN4: W+22 | AO4: W+24 | AP4: W+26 | AQ4: W+28 | AR4: W+30 | AS4: W+32 | AT4: W+34 | AU4: W+36
M5: -32 | N5: -30 | O5: -28 | P5: -26 | Q5: -24 | R5: -22 | S5: -20 | T5: -18 | U5: -16 | V5: -14 | W5: -12 | X5: -10 | Y5: -8 | Z5: -6 | AA5: -4 | AB5: -2 | AC5: 0 | AD5: 2 | AE5: 4 | AF5: 6 | AG5: 8 | AH5: 10 | AI5: 12 | AJ5: 14 | AK5: 16 | AL5: 18 | AM5: 20 | AN5: 22 | AO5: 24 | AP5: 26 | AQ5: 28 | AR5: 30 | AS5: 32 | AT5: 34 | AU5: 36
A6: ▶ SECTION 1 : Civil / Structural 선행공정 (Pipe Rack · Building · Sleeper/Embed)
A7: 1 | B7: CIVIL | C7: RACK | D7: Pipe Rack 기초 공사 | E7: CIVIL | F7: 8 | G7: =DATA!K2 -> -28 | H7: =DATA!L2 -> -20 | I7: =DATA!O2 -> -28 | J7: =DATA!P2 -> -20 | K7: =DATA!N2 -> 0 | L7: 8 | M7: =IF(AND(M$5>=$I7,M$5<$J7),IF(AND(M$5>=$G7,M$5<$H7),$L7,$L7+100),IF(AND(M$5>=$G7,M$5<$H7),-1,0)) -> 0 | N7: =IF(AND(N$5>=$I7,N$5<$J7),IF(AND(N$5>=$G7,N$5<$H7),$L7,$L7+100),IF(AND(N$5>=$G7,N$5<$H7),-1,0)) -> 0 | O7: =IF(AND(O$5>=$I7,O$5<$J7),IF(AND(O$5>=$G7,O$5<$H7),$L7,$L7+100),IF(AND(O$5>=$G7,O$5<$H7),-1,0)) -> 8 | P7: =IF(AND(P$5>=$I7,P$5<$J7),IF(AND(P$5>=$G7,P$5<$H7),$L7,$L7+100),IF(AND(P$5>=$G7,P$5<$H7),-1,0)) -> 8 | Q7: =IF(AND(Q$5>=$I7,Q$5<$J7),IF(AND(Q$5>=$G7,Q$5<$H7),$L7,$L7+100),IF(AND(Q$5>=$G7,Q$5<$H7),-1,0)) -> 8 | R7: =IF(AND(R$5>=$I7,R$5<$J7),IF(AND(R$5>=$G7,R$5<$H7),$L7,$L7+100),IF(AND(R$5>=$G7,R$5<$H7),-1,0)) -> 8 | S7: =IF(AND(S$5>=$I7,S$5<$J7),IF(AND(S$5>=$G7,S$5<$H7),$L7,$L7+100),IF(AND(S$5>=$G7,S$5<$H7),-1,0)) -> 0 | T7: =IF(AND(T$5>=$I7,T$5<$J7),IF(AND(T$5>=$G7,T$5<$H7),$L7,$L7+100),IF(AND(T$5>=$G7,T$5<$H7),-1,0)) -> 0 | ... AU7: =IF(AND(AU$5>=$I7,AU$5<$J7),IF(AND(AU$5>=$G7,AU$5<$H7),$L7,$L7+100),IF(AND(AU$5>=$G7,AU$5<$H7),-1,0)) -> 0
A8: 2 | B8: CIVIL | C8: RACK | D8: Pipe Rack 철골 제작 | E8: CIVIL | F8: 12 | G8: =DATA!K3 -> -24 | H8: =DATA!L3 -> -12 | I8: =DATA!O3 -> -24 | J8: =DATA!P3 -> -12 | K8: =DATA!N3 -> 0 | L8: 8 | M8: =IF(AND(M$5>=$I8,M$5<$J8),IF(AND(M$5>=$G8,M$5<$H8),$L8,$L8+100),IF(AND(M$5>=$G8,M$5<$H8),-1,0)) -> 0 | N8: =IF(AND(N$5>=$I8,N$5<$J8),IF(AND(N$5>=$G8,N$5<$H8),$L8,$L8+100),IF(AND(N$5>=$G8,N$5<$H8),-1,0)) -> 0 | O8: =IF(AND(O$5>=$I8,O$5<$J8),IF(AND(O$5>=$G8,O$5<$H8),$L8,$L8+100),IF(AND(O$5>=$G8,O$5<$H8),-1,0)) -> 0 | P8: =IF(AND(P$5>=$I8,P$5<$J8),IF(AND(P$5>=$G8,P$5<$H8),$L8,$L8+100),IF(AND(P$5>=$G8,P$5<$H8),-1,0)) -> 0 | Q8: =IF(AND(Q$5>=$I8,Q$5<$J8),IF(AND(Q$5>=$G8,Q$5<$H8),$L8,$L8+100),IF(AND(Q$5>=$G8,Q$5<$H8),-1,0)) -> 8 | R8: =IF(AND(R$5>=$I8,R$5<$J8),IF(AND(R$5>=$G8,R$5<$H8),$L8,$L8+100),IF(AND(R$5>=$G8,R$5<$H8),-1,0)) -> 8 | S8: =IF(AND(S$5>=$I8,S$5<$J8),IF(AND(S$5>=$G8,S$5<$H8),$L8,$L8+100),IF(AND(S$5>=$G8,S$5<$H8),-1,0)) -> 8 | T8: =IF(AND(T$5>=$I8,T$5<$J8),IF(AND(T$5>=$G8,T$5<$H8),$L8,$L8+100),IF(AND(T$5>=$G8,T$5<$H8),-1,0)) -> 8 | ... AU8: =IF(AND(AU$5>=$I8,AU$5<$J8),IF(AND(AU$5>=$G8,AU$5<$H8),$L8,$L8+100),IF(AND(AU$5>=$G8,AU$5<$H8),-1,0)) -> 0
A9: 3 | B9: CIVIL | C9: RACK | D9: Pipe Rack 철골 설치 | E9: CIVIL | F9: 8 | G9: =DATA!K4 -> -14 | H9: =DATA!L4 -> -6 | I9: =DATA!O4 -> -14 | J9: =DATA!P4 -> -6 | K9: =DATA!N4 -> 0 | L9: 8 | M9: =IF(AND(M$5>=$I9,M$5<$J9),IF(AND(M$5>=$G9,M$5<$H9),$L9,$L9+100),IF(AND(M$5>=$G9,M$5<$H9),-1,0)) -> 0 | N9: =IF(AND(N$5>=$I9,N$5<$J9),IF(AND(N$5>=$G9,N$5<$H9),$L9,$L9+100),IF(AND(N$5>=$G9,N$5<$H9),-1,0)) -> 0 | O9: =IF(AND(O$5>=$I9,O$5<$J9),IF(AND(O$5>=$G9,O$5<$H9),$L9,$L9+100),IF(AND(O$5>=$G9,O$5<$H9),-1,0)) -> 0 | P9: =IF(AND(P$5>=$I9,P$5<$J9),IF(AND(P$5>=$G9,P$5<$H9),$L9,$L9+100),IF(AND(P$5>=$G9,P$5<$H9),-1,0)) -> 0 | Q9: =IF(AND(Q$5>=$I9,Q$5<$J9),IF(AND(Q$5>=$G9,Q$5<$H9),$L9,$L9+100),IF(AND(Q$5>=$G9,Q$5<$H9),-1,0)) -> 0 | R9: =IF(AND(R$5>=$I9,R$5<$J9),IF(AND(R$5>=$G9,R$5<$H9),$L9,$L9+100),IF(AND(R$5>=$G9,R$5<$H9),-1,0)) -> 0 | S9: =IF(AND(S$5>=$I9,S$5<$J9),IF(AND(S$5>=$G9,S$5<$H9),$L9,$L9+100),IF(AND(S$5>=$G9,S$5<$H9),-1,0)) -> 0 | T9: =IF(AND(T$5>=$I9,T$5<$J9),IF(AND(T$5>=$G9,T$5<$H9),$L9,$L9+100),IF(AND(T$5>=$G9,T$5<$H9),-1,0)) -> 0 | ... AU9: =IF(AND(AU$5>=$I9,AU$5<$J9),IF(AND(AU$5>=$G9,AU$5<$H9),$L9,$L9+100),IF(AND(AU$5>=$G9,AU$5<$H9),-1,0)) -> 0
A10: 4 | B10: CIVIL | C10: RACK | D10: Grating / Floor 설치 | E10: CIVIL | F10: 4 | G10: =DATA!K5 -> -6 | H10: =DATA!L5 -> -2 | I10: =DATA!O5 -> -6 | J10: =DATA!P5 -> -2 | K10: =DATA!N5 -> 0 | L10: 8 | M10: =IF(AND(M$5>=$I10,M$5<$J10),IF(AND(M$5>=$G10,M$5<$H10),$L10,$L10+100),IF(AND(M$5>=$G10,M$5<$H10),-1,0)) -> 0 | N10: =IF(AND(N$5>=$I10,N$5<$J10),IF(AND(N$5>=$G10,N$5<$H10),$L10,$L10+100),IF(AND(N$5>=$G10,N$5<$H10),-1,0)) -> 0 | O10: =IF(AND(O$5>=$I10,O$5<$J10),IF(AND(O$5>=$G10,O$5<$H10),$L10,$L10+100),IF(AND(O$5>=$G10,O$5<$H10),-1,0)) -> 0 | P10: =IF(AND(P$5>=$I10,P$5<$J10),IF(AND(P$5>=$G10,P$5<$H10),$L10,$L10+100),IF(AND(P$5>=$G10,P$5<$H10),-1,0)) -> 0 | Q10: =IF(AND(Q$5>=$I10,Q$5<$J10),IF(AND(Q$5>=$G10,Q$5<$H10),$L10,$L10+100),IF(AND(Q$5>=$G10,Q$5<$H10),-1,0)) -> 0 | R10: =IF(AND(R$5>=$I10,R$5<$J10),IF(AND(R$5>=$G10,R$5<$H10),$L10,$L10+100),IF(AND(R$5>=$G10,R$5<$H10),-1,0)) -> 0 | S10: =IF(AND(S$5>=$I10,S$5<$J10),IF(AND(S$5>=$G10,S$5<$H10),$L10,$L10+100),IF(AND(S$5>=$G10,S$5<$H10),-1,0)) -> 0 | T10: =IF(AND(T$5>=$I10,T$5<$J10),IF(AND(T$5>=$G10,T$5<$H10),$L10,$L10+100),IF(AND(T$5>=$G10,T$5<$H10),-1,0)) -> 0 | ... AU10: =IF(AND(AU$5>=$I10,AU$5<$J10),IF(AND(AU$5>=$G10,AU$5<$H10),$L10,$L10+100),IF(AND(AU$5>=$G10,AU$5<$H10),-1,0)) -> 0
A11: 5 | B11: CIVIL | C11: BLDG | D11: 터파기 / 철근 배근 | E11: CIVIL | F11: 6 | G11: =DATA!K6 -> -28 | H11: =DATA!L6 -> -22 | I11: =DATA!O6 -> -28 | J11: =DATA!P6 -> -22 | K11: =DATA!N6 -> 0 | L11: 9 | M11: =IF(AND(M$5>=$I11,M$5<$J11),IF(AND(M$5>=$G11,M$5<$H11),$L11,$L11+100),IF(AND(M$5>=$G11,M$5<$H11),-1,0)) -> 0 | N11: =IF(AND(N$5>=$I11,N$5<$J11),IF(AND(N$5>=$G11,N$5<$H11),$L11,$L11+100),IF(AND(N$5>=$G11,N$5<$H11),-1,0)) -> 0 | O11: =IF(AND(O$5>=$I11,O$5<$J11),IF(AND(O$5>=$G11,O$5<$H11),$L11,$L11+100),IF(AND(O$5>=$G11,O$5<$H11),-1,0)) -> 9 | P11: =IF(AND(P$5>=$I11,P$5<$J11),IF(AND(P$5>=$G11,P$5<$H11),$L11,$L11+100),IF(AND(P$5>=$G11,P$5<$H11),-1,0)) -> 9 | Q11: =IF(AND(Q$5>=$I11,Q$5<$J11),IF(AND(Q$5>=$G11,Q$5<$H11),$L11,$L11+100),IF(AND(Q$5>=$G11,Q$5<$H11),-1,0)) -> 9 | R11: =IF(AND(R$5>=$I11,R$5<$J11),IF(AND(R$5>=$G11,R$5<$H11),$L11,$L11+100),IF(AND(R$5>=$G11,R$5<$H11),-1,0)) -> 0 | S11: =IF(AND(S$5>=$I11,S$5<$J11),IF(AND(S$5>=$G11,S$5<$H11),$L11,$L11+100),IF(AND(S$5>=$G11,S$5<$H11),-1,0)) -> 0 | T11: =IF(AND(T$5>=$I11,T$5<$J11),IF(AND(T$5>=$G11,T$5<$H11),$L11,$L11+100),IF(AND(T$5>=$G11,T$5<$H11),-1,0)) -> 0 | ... AU11: =IF(AND(AU$5>=$I11,AU$5<$J11),IF(AND(AU$5>=$G11,AU$5<$H11),$L11,$L11+100),IF(AND(AU$5>=$G11,AU$5<$H11),-1,0)) -> 0
A12: 6 | B12: CIVIL | C12: BLDG | D12: 콘크리트 타설 (양생) | E12: CIVIL | F12: 8 | G12: =DATA!K7 -> -22 | H12: =DATA!L7 -> -14 | I12: =DATA!O7 -> -22 | J12: =DATA!P7 -> -14 | K12: =DATA!N7 -> 0 | L12: 9 | M12: =IF(AND(M$5>=$I12,M$5<$J12),IF(AND(M$5>=$G12,M$5<$H12),$L12,$L12+100),IF(AND(M$5>=$G12,M$5<$H12),-1,0)) -> 0 | N12: =IF(AND(N$5>=$I12,N$5<$J12),IF(AND(N$5>=$G12,N$5<$H12),$L12,$L12+100),IF(AND(N$5>=$G12,N$5<$H12),-1,0)) -> 0 | O12: =IF(AND(O$5>=$I12,O$5<$J12),IF(AND(O$5>=$G12,O$5<$H12),$L12,$L12+100),IF(AND(O$5>=$G12,O$5<$H12),-1,0)) -> 0 | P12: =IF(AND(P$5>=$I12,P$5<$J12),IF(AND(P$5>=$G12,P$5<$H12),$L12,$L12+100),IF(AND(P$5>=$G12,P$5<$H12),-1,0)) -> 0 | Q12: =IF(AND(Q$5>=$I12,Q$5<$J12),IF(AND(Q$5>=$G12,Q$5<$H12),$L12,$L12+100),IF(AND(Q$5>=$G12,Q$5<$H12),-1,0)) -> 0 | R12: =IF(AND(R$5>=$I12,R$5<$J12),IF(AND(R$5>=$G12,R$5<$H12),$L12,$L12+100),IF(AND(R$5>=$G12,R$5<$H12),-1,0)) -> 9 | S12: =IF(AND(S$5>=$I12,S$5<$J12),IF(AND(S$5>=$G12,S$5<$H12),$L12,$L12+100),IF(AND(S$5>=$G12,S$5<$H12),-1,0)) -> 9 | T12: =IF(AND(T$5>=$I12,T$5<$J12),IF(AND(T$5>=$G12,T$5<$H12),$L12,$L12+100),IF(AND(T$5>=$G12,T$5<$H12),-1,0)) -> 9 | ... AU12: =IF(AND(AU$5>=$I12,AU$5<$J12),IF(AND(AU$5>=$G12,AU$5<$H12),$L12,$L12+100),IF(AND(AU$5>=$G12,AU$5<$H12),-1,0)) -> 0
A13: 7 | B13: CIVIL | C13: BLDG | D13: 내부 구조물 / 지붕 공사 | E13: CIVIL | F13: 8 | G13: =DATA!K8 -> -14 | H13: =DATA!L8 -> -6 | I13: =DATA!O8 -> -14 | J13: =DATA!P8 -> -6 | K13: =DATA!N8 -> 0 | L13: 9 | M13: =IF(AND(M$5>=$I13,M$5<$J13),IF(AND(M$5>=$G13,M$5<$H13),$L13,$L13+100),IF(AND(M$5>=$G13,M$5<$H13),-1,0)) -> 0 | N13: =IF(AND(N$5>=$I13,N$5<$J13),IF(AND(N$5>=$G13,N$5<$H13),$L13,$L13+100),IF(AND(N$5>=$G13,N$5<$H13),-1,0)) -> 0 | O13: =IF(AND(O$5>=$I13,O$5<$J13),IF(AND(O$5>=$G13,O$5<$H13),$L13,$L13+100),IF(AND(O$5>=$G13,O$5<$H13),-1,0)) -> 0 | P13: =IF(AND(P$5>=$I13,P$5<$J13),IF(AND(P$5>=$G13,P$5<$H13),$L13,$L13+100),IF(AND(P$5>=$G13,P$5<$H13),-1,0)) -> 0 | Q13: =IF(AND(Q$5>=$I13,Q$5<$J13),IF(AND(Q$5>=$G13,Q$5<$H13),$L13,$L13+100),IF(AND(Q$5>=$G13,Q$5<$H13),-1,0)) -> 0 | R13: =IF(AND(R$5>=$I13,R$5<$J13),IF(AND(R$5>=$G13,R$5<$H13),$L13,$L13+100),IF(AND(R$5>=$G13,R$5<$H13),-1,0)) -> 0 | S13: =IF(AND(S$5>=$I13,S$5<$J13),IF(AND(S$5>=$G13,S$5<$H13),$L13,$L13+100),IF(AND(S$5>=$G13,S$5<$H13),-1,0)) -> 0 | T13: =IF(AND(T$5>=$I13,T$5<$J13),IF(AND(T$5>=$G13,T$5<$H13),$L13,$L13+100),IF(AND(T$5>=$G13,T$5<$H13),-1,0)) -> 0 | ... AU13: =IF(AND(AU$5>=$I13,AU$5<$J13),IF(AND(AU$5>=$G13,AU$5<$H13),$L13,$L13+100),IF(AND(AU$5>=$G13,AU$5<$H13),-1,0)) -> 0
A14: 8 | B14: CIVIL | C14: SLP | D14: Support Embed (지하/매립) | E14: CIVIL | F14: 4 | G14: =DATA!K9 -> -18 | H14: =DATA!L9 -> -14 | I14: =DATA!O9 -> -18 | J14: =DATA!P9 -> -14 | K14: =DATA!N9 -> 0 | L14: 10 | M14: =IF(AND(M$5>=$I14,M$5<$J14),IF(AND(M$5>=$G14,M$5<$H14),$L14,$L14+100),IF(AND(M$5>=$G14,M$5<$H14),-1,0)) -> 0 | N14: =IF(AND(N$5>=$I14,N$5<$J14),IF(AND(N$5>=$G14,N$5<$H14),$L14,$L14+100),IF(AND(N$5>=$G14,N$5<$H14),-1,0)) -> 0 | O14: =IF(AND(O$5>=$I14,O$5<$J14),IF(AND(O$5>=$G14,O$5<$H14),$L14,$L14+100),IF(AND(O$5>=$G14,O$5<$H14),-1,0)) -> 0 | P14: =IF(AND(P$5>=$I14,P$5<$J14),IF(AND(P$5>=$G14,P$5<$H14),$L14,$L14+100),IF(AND(P$5>=$G14,P$5<$H14),-1,0)) -> 0 | Q14: =IF(AND(Q$5>=$I14,Q$5<$J14),IF(AND(Q$5>=$G14,Q$5<$H14),$L14,$L14+100),IF(AND(Q$5>=$G14,Q$5<$H14),-1,0)) -> 0 | R14: =IF(AND(R$5>=$I14,R$5<$J14),IF(AND(R$5>=$G14,R$5<$H14),$L14,$L14+100),IF(AND(R$5>=$G14,R$5<$H14),-1,0)) -> 0 | S14: =IF(AND(S$5>=$I14,S$5<$J14),IF(AND(S$5>=$G14,S$5<$H14),$L14,$L14+100),IF(AND(S$5>=$G14,S$5<$H14),-1,0)) -> 0 | T14: =IF(AND(T$5>=$I14,T$5<$J14),IF(AND(T$5>=$G14,T$5<$H14),$L14,$L14+100),IF(AND(T$5>=$G14,T$5<$H14),-1,0)) -> 10 | ... AU14: =IF(AND(AU$5>=$I14,AU$5<$J14),IF(AND(AU$5>=$G14,AU$5<$H14),$L14,$L14+100),IF(AND(AU$5>=$G14,AU$5<$H14),-1,0)) -> 0
A15: 9 | B15: CIVIL | C15: SLP | D15: Pipe Sleeper 설치 (지상) | E15: CIVIL | F15: 4 | G15: =DATA!K10 -> -10 | H15: =DATA!L10 -> -6 | I15: =DATA!O10 -> -10 | J15: =DATA!P10 -> -6 | K15: =DATA!N10 -> 0 | L15: 10 | M15: =IF(AND(M$5>=$I15,M$5<$J15),IF(AND(M$5>=$G15,M$5<$H15),$L15,$L15+100),IF(AND(M$5>=$G15,M$5<$H15),-1,0)) -> 0 | N15: =IF(AND(N$5>=$I15,N$5<$J15),IF(AND(N$5>=$G15,N$5<$H15),$L15,$L15+100),IF(AND(N$5>=$G15,N$5<$H15),-1,0)) -> 0 | O15: =IF(AND(O$5>=$I15,O$5<$J15),IF(AND(O$5>=$G15,O$5<$H15),$L15,$L15+100),IF(AND(O$5>=$G15,O$5<$H15),-1,0)) -> 0 | P15: =IF(AND(P$5>=$I15,P$5<$J15),IF(AND(P$5>=$G15,P$5<$H15),$L15,$L15+100),IF(AND(P$5>=$G15,P$5<$H15),-1,0)) -> 0 | Q15: =IF(AND(Q$5>=$I15,Q$5<$J15),IF(AND(Q$5>=$G15,Q$5<$H15),$L15,$L15+100),IF(AND(Q$5>=$G15,Q$5<$H15),-1,0)) -> 0 | R15: =IF(AND(R$5>=$I15,R$5<$J15),IF(AND(R$5>=$G15,R$5<$H15),$L15,$L15+100),IF(AND(R$5>=$G15,R$5<$H15),-1,0)) -> 0 | S15: =IF(AND(S$5>=$I15,S$5<$J15),IF(AND(S$5>=$G15,S$5<$H15),$L15,$L15+100),IF(AND(S$5>=$G15,S$5<$H15),-1,0)) -> 0 | T15: =IF(AND(T$5>=$I15,T$5<$J15),IF(AND(T$5>=$G15,T$5<$H15),$L15,$L15+100),IF(AND(T$5>=$G15,T$5<$H15),-1,0)) -> 0 | ... AU15: =IF(AND(AU$5>=$I15,AU$5<$J15),IF(AND(AU$5>=$G15,AU$5<$H15),$L15,$L15+100),IF(AND(AU$5>=$G15,AU$5<$H15),-1,0)) -> 0
A16: 10 | B16: CIVIL | C16: SLP | D16: Anchor Bolt / Clip 확인 | E16: CIVIL | F16: 2 | G16: =DATA!K11 -> -4 | H16: =DATA!L11 -> -2 | I16: =DATA!O11 -> -4 | J16: =DATA!P11 -> -2 | K16: =DATA!N11 -> 0 | L16: 10 | M16: =IF(AND(M$5>=$I16,M$5<$J16),IF(AND(M$5>=$G16,M$5<$H16),$L16,$L16+100),IF(AND(M$5>=$G16,M$5<$H16),-1,0)) -> 0 | N16: =IF(AND(N$5>=$I16,N$5<$J16),IF(AND(N$5>=$G16,N$5<$H16),$L16,$L16+100),IF(AND(N$5>=$G16,N$5<$H16),-1,0)) -> 0 | O16: =IF(AND(O$5>=$I16,O$5<$J16),IF(AND(O$5>=$G16,O$5<$H16),$L16,$L16+100),IF(AND(O$5>=$G16,O$5<$H16),-1,0)) -> 0 | P16: =IF(AND(P$5>=$I16,P$5<$J16),IF(AND(P$5>=$G16,P$5<$H16),$L16,$L16+100),IF(AND(P$5>=$G16,P$5<$H16),-1,0)) -> 0 | Q16: =IF(AND(Q$5>=$I16,Q$5<$J16),IF(AND(Q$5>=$G16,Q$5<$H16),$L16,$L16+100),IF(AND(Q$5>=$G16,Q$5<$H16),-1,0)) -> 0 | R16: =IF(AND(R$5>=$I16,R$5<$J16),IF(AND(R$5>=$G16,R$5<$H16),$L16,$L16+100),IF(AND(R$5>=$G16,R$5<$H16),-1,0)) -> 0 | S16: =IF(AND(S$5>=$I16,S$5<$J16),IF(AND(S$5>=$G16,S$5<$H16),$L16,$L16+100),IF(AND(S$5>=$G16,S$5<$H16),-1,0)) -> 0 | T16: =IF(AND(T$5>=$I16,T$5<$J16),IF(AND(T$5>=$G16,T$5<$H16),$L16,$L16+100),IF(AND(T$5>=$G16,T$5<$H16),-1,0)) -> 0 | ... AU16: =IF(AND(AU$5>=$I16,AU$5<$J16),IF(AND(AU$5>=$G16,AU$5<$H16),$L16,$L16+100),IF(AND(AU$5>=$G16,AU$5<$H16),-1,0)) -> 0
A17: ▶ SECTION 2 : BOP Piping Construction (시스템별 · 선행공정 의존성 반영)
A18: 01. CWS — 냉각수 계통 (Cooling Water) | 주요 Civil 의존: NONE
A19: 11 | B19: PIPING | C19: CWS | D19: MR 발행 / 자재 발주 | E19: PROC | F19: 10 | G19: =DATA!K12 -> -16 | H19: =DATA!L12 -> -6 | I19: =DATA!O12 -> -16 | J19: =DATA!P12 -> -6 | K19: =DATA!N12 -> 0 | L19: 1 | M19: =IF(AND(M$5>=$I19,M$5<$J19),IF(AND(M$5>=$G19,M$5<$H19),$L19,$L19+100),IF(AND(M$5>=$G19,M$5<$H19),-1,0)) -> 0 | N19: =IF(AND(N$5>=$I19,N$5<$J19),IF(AND(N$5>=$G19,N$5<$H19),$L19,$L19+100),IF(AND(N$5>=$G19,N$5<$H19),-1,0)) -> 0 | O19: =IF(AND(O$5>=$I19,O$5<$J19),IF(AND(O$5>=$G19,O$5<$H19),$L19,$L19+100),IF(AND(O$5>=$G19,O$5<$H19),-1,0)) -> 0 | P19: =IF(AND(P$5>=$I19,P$5<$J19),IF(AND(P$5>=$G19,P$5<$H19),$L19,$L19+100),IF(AND(P$5>=$G19,P$5<$H19),-1,0)) -> 0 | Q19: =IF(AND(Q$5>=$I19,Q$5<$J19),IF(AND(Q$5>=$G19,Q$5<$H19),$L19,$L19+100),IF(AND(Q$5>=$G19,Q$5<$H19),-1,0)) -> 0 | R19: =IF(AND(R$5>=$I19,R$5<$J19),IF(AND(R$5>=$G19,R$5<$H19),$L19,$L19+100),IF(AND(R$5>=$G19,R$5<$H19),-1,0)) -> 0 | S19: =IF(AND(S$5>=$I19,S$5<$J19),IF(AND(S$5>=$G19,S$5<$H19),$L19,$L19+100),IF(AND(S$5>=$G19,S$5<$H19),-1,0)) -> 0 | T19: =IF(AND(T$5>=$I19,T$5<$J19),IF(AND(T$5>=$G19,T$5<$H19),$L19,$L19+100),IF(AND(T$5>=$G19,T$5<$H19),-1,0)) -> 0 | ... AU19: =IF(AND(AU$5>=$I19,AU$5<$J19),IF(AND(AU$5>=$G19,AU$5<$H19),$L19,$L19+100),IF(AND(AU$5>=$G19,AU$5<$H19),-1,0)) -> 0
A20: 12 | B20: PIPING | C20: CWS | D20: 자재 입고 | E20: PROC | F20: 8 | G20: =DATA!K13 -> -6 | H20: =DATA!L13 -> 2 | I20: =DATA!O13 -> -6 | J20: =DATA!P13 -> 2 | K20: =DATA!N13 -> 0 | L20: 2 | M20: =IF(AND(M$5>=$I20,M$5<$J20),IF(AND(M$5>=$G20,M$5<$H20),$L20,$L20+100),IF(AND(M$5>=$G20,M$5<$H20),-1,0)) -> 0 | N20: =IF(AND(N$5>=$I20,N$5<$J20),IF(AND(N$5>=$G20,N$5<$H20),$L20,$L20+100),IF(AND(N$5>=$G20,N$5<$H20),-1,0)) -> 0 | O20: =IF(AND(O$5>=$I20,O$5<$J20),IF(AND(O$5>=$G20,O$5<$H20),$L20,$L20+100),IF(AND(O$5>=$G20,O$5<$H20),-1,0)) -> 0 | P20: =IF(AND(P$5>=$I20,P$5<$J20),IF(AND(P$5>=$G20,P$5<$H20),$L20,$L20+100),IF(AND(P$5>=$G20,P$5<$H20),-1,0)) -> 0 | Q20: =IF(AND(Q$5>=$I20,Q$5<$J20),IF(AND(Q$5>=$G20,Q$5<$H20),$L20,$L20+100),IF(AND(Q$5>=$G20,Q$5<$H20),-1,0)) -> 0 | R20: =IF(AND(R$5>=$I20,R$5<$J20),IF(AND(R$5>=$G20,R$5<$H20),$L20,$L20+100),IF(AND(R$5>=$G20,R$5<$H20),-1,0)) -> 0 | S20: =IF(AND(S$5>=$I20,S$5<$J20),IF(AND(S$5>=$G20,S$5<$H20),$L20,$L20+100),IF(AND(S$5>=$G20,S$5<$H20),-1,0)) -> 0 | T20: =IF(AND(T$5>=$I20,T$5<$J20),IF(AND(T$5>=$G20,T$5<$H20),$L20,$L20+100),IF(AND(T$5>=$G20,T$5<$H20),-1,0)) -> 0 | ... AU20: =IF(AND(AU$5>=$I20,AU$5<$J20),IF(AND(AU$5>=$G20,AU$5<$H20),$L20,$L20+100),IF(AND(AU$5>=$G20,AU$5<$H20),-1,0)) -> 0
A21: 13 | B21: PIPING | C21: CWS | D21: Spool 제작 | E21: PROC | F21: 6 | G21: =DATA!K14 -> 0 | H21: =DATA!L14 -> 6 | I21: =DATA!O14 -> 0 | J21: =DATA!P14 -> 6 | K21: =DATA!N14 -> 0 | L21: 3 | M21: =IF(AND(M$5>=$I21,M$5<$J21),IF(AND(M$5>=$G21,M$5<$H21),$L21,$L21+100),IF(AND(M$5>=$G21,M$5<$H21),-1,0)) -> 0 | N21: =IF(AND(N$5>=$I21,N$5<$J21),IF(AND(N$5>=$G21,N$5<$H21),$L21,$L21+100),IF(AND(N$5>=$G21,N$5<$H21),-1,0)) -> 0 | O21: =IF(AND(O$5>=$I21,O$5<$J21),IF(AND(O$5>=$G21,O$5<$H21),$L21,$L21+100),IF(AND(O$5>=$G21,O$5<$H21),-1,0)) -> 0 | P21: =IF(AND(P$5>=$I21,P$5<$J21),IF(AND(P$5>=$G21,P$5<$H21),$L21,$L21+100),IF(AND(P$5>=$G21,P$5<$H21),-1,0)) -> 0 | Q21: =IF(AND(Q$5>=$I21,Q$5<$J21),IF(AND(Q$5>=$G21,Q$5<$H21),$L21,$L21+100),IF(AND(Q$5>=$G21,Q$5<$H21),-1,0)) -> 0 | R21: =IF(AND(R$5>=$I21,R$5<$J21),IF(AND(R$5>=$G21,R$5<$H21),$L21,$L21+100),IF(AND(R$5>=$G21,R$5<$H21),-1,0)) -> 0 | S21: =IF(AND(S$5>=$I21,S$5<$J21),IF(AND(S$5>=$G21,S$5<$H21),$L21,$L21+100),IF(AND(S$5>=$G21,S$5<$H21),-1,0)) -> 0 | T21: =IF(AND(T$5>=$I21,T$5<$J21),IF(AND(T$5>=$G21,T$5<$H21),$L21,$L21+100),IF(AND(T$5>=$G21,T$5<$H21),-1,0)) -> 0 | ... AU21: =IF(AND(AU$5>=$I21,AU$5<$J21),IF(AND(AU$5>=$G21,AU$5<$H21),$L21,$L21+100),IF(AND(AU$5>=$G21,AU$5<$H21),-1,0)) -> 0
A22: 14 | B22: PIPING | C22: CWS | D22: 현장 배관 설치 | E22: FIELD | F22: 10 | G22: =DATA!K15 -> 4 | H22: =DATA!L15 -> 14 | I22: =DATA!O15 -> 4 | J22: =DATA!P15 -> 14 | K22: =DATA!N15 -> 0 | L22: 4 | M22: =IF(AND(M$5>=$I22,M$5<$J22),IF(AND(M$5>=$G22,M$5<$H22),$L22,$L22+100),IF(AND(M$5>=$G22,M$5<$H22),-1,0)) -> 0 | N22: =IF(AND(N$5>=$I22,N$5<$J22),IF(AND(N$5>=$G22,N$5<$H22),$L22,$L22+100),IF(AND(N$5>=$G22,N$5<$H22),-1,0)) -> 0 | O22: =IF(AND(O$5>=$I22,O$5<$J22),IF(AND(O$5>=$G22,O$5<$H22),$L22,$L22+100),IF(AND(O$5>=$G22,O$5<$H22),-1,0)) -> 0 | P22: =IF(AND(P$5>=$I22,P$5<$J22),IF(AND(P$5>=$G22,P$5<$H22),$L22,$L22+100),IF(AND(P$5>=$G22,P$5<$H22),-1,0)) -> 0 | Q22: =IF(AND(Q$5>=$I22,Q$5<$J22),IF(AND(Q$5>=$G22,Q$5<$H22),$L22,$L22+100),IF(AND(Q$5>=$G22,Q$5<$H22),-1,0)) -> 0 | R22: =IF(AND(R$5>=$I22,R$5<$J22),IF(AND(R$5>=$G22,R$5<$H22),$L22,$L22+100),IF(AND(R$5>=$G22,R$5<$H22),-1,0)) -> 0 | S22: =IF(AND(S$5>=$I22,S$5<$J22),IF(AND(S$5>=$G22,S$5<$H22),$L22,$L22+100),IF(AND(S$5>=$G22,S$5<$H22),-1,0)) -> 0 | T22: =IF(AND(T$5>=$I22,T$5<$J22),IF(AND(T$5>=$G22,T$5<$H22),$L22,$L22+100),IF(AND(T$5>=$G22,T$5<$H22),-1,0)) -> 0 | ... AU22: =IF(AND(AU$5>=$I22,AU$5<$J22),IF(AND(AU$5>=$G22,AU$5<$H22),$L22,$L22+100),IF(AND(AU$5>=$G22,AU$5<$H22),-1,0)) -> 0
A23: 15 | B23: PIPING | C23: CWS | D23: Support 최종 설치/정렬 | E23: FIELD | F23: 2 | G23: =DATA!K16 -> 14 | H23: =DATA!L16 -> 16 | I23: =DATA!O16 -> 14 | J23: =DATA!P16 -> 16 | K23: =DATA!N16 -> 0 | L23: 5 | M23: =IF(AND(M$5>=$I23,M$5<$J23),IF(AND(M$5>=$G23,M$5<$H23),$L23,$L23+100),IF(AND(M$5>=$G23,M$5<$H23),-1,0)) -> 0 | N23: =IF(AND(N$5>=$I23,N$5<$J23),IF(AND(N$5>=$G23,N$5<$H23),$L23,$L23+100),IF(AND(N$5>=$G23,N$5<$H23),-1,0)) -> 0 | O23: =IF(AND(O$5>=$I23,O$5<$J23),IF(AND(O$5>=$G23,O$5<$H23),$L23,$L23+100),IF(AND(O$5>=$G23,O$5<$H23),-1,0)) -> 0 | P23: =IF(AND(P$5>=$I23,P$5<$J23),IF(AND(P$5>=$G23,P$5<$H23),$L23,$L23+100),IF(AND(P$5>=$G23,P$5<$H23),-1,0)) -> 0 | Q23: =IF(AND(Q$5>=$I23,Q$5<$J23),IF(AND(Q$5>=$G23,Q$5<$H23),$L23,$L23+100),IF(AND(Q$5>=$G23,Q$5<$H23),-1,0)) -> 0 | R23: =IF(AND(R$5>=$I23,R$5<$J23),IF(AND(R$5>=$G23,R$5<$H23),$L23,$L23+100),IF(AND(R$5>=$G23,R$5<$H23),-1,0)) -> 0 | S23: =IF(AND(S$5>=$I23,S$5<$J23),IF(AND(S$5>=$G23,S$5<$H23),$L23,$L23+100),IF(AND(S$5>=$G23,S$5<$H23),-1,0)) -> 0 | T23: =IF(AND(T$5>=$I23,T$5<$J23),IF(AND(T$5>=$G23,T$5<$H23),$L23,$L23+100),IF(AND(T$5>=$G23,T$5<$H23),-1,0)) -> 0 | ... AU23: =IF(AND(AU$5>=$I23,AU$5<$J23),IF(AND(AU$5>=$G23,AU$5<$H23),$L23,$L23+100),IF(AND(AU$5>=$G23,AU$5<$H23),-1,0)) -> 0
A24: 16 | B24: PIPING | C24: CWS | D24: 수압시험 (Hydro Test) | E24: FIELD | F24: 2 | G24: =DATA!K17 -> 16 | H24: =DATA!L17 -> 18 | I24: =DATA!O17 -> 16 | J24: =DATA!P17 -> 18 | K24: =DATA!N17 -> 0 | L24: 6 | M24: =IF(AND(M$5>=$I24,M$5<$J24),IF(AND(M$5>=$G24,M$5<$H24),$L24,$L24+100),IF(AND(M$5>=$G24,M$5<$H24),-1,0)) -> 0 | N24: =IF(AND(N$5>=$I24,N$5<$J24),IF(AND(N$5>=$G24,N$5<$H24),$L24,$L24+100),IF(AND(N$5>=$G24,N$5<$H24),-1,0)) -> 0 | O24: =IF(AND(O$5>=$I24,O$5<$J24),IF(AND(O$5>=$G24,O$5<$H24),$L24,$L24+100),IF(AND(O$5>=$G24,O$5<$H24),-1,0)) -> 0 | P24: =IF(AND(P$5>=$I24,P$5<$J24),IF(AND(P$5>=$G24,P$5<$H24),$L24,$L24+100),IF(AND(P$5>=$G24,P$5<$H24),-1,0)) -> 0 | Q24: =IF(AND(Q$5>=$I24,Q$5<$J24),IF(AND(Q$5>=$G24,Q$5<$H24),$L24,$L24+100),IF(AND(Q$5>=$G24,Q$5<$H24),-1,0)) -> 0 | R24: =IF(AND(R$5>=$I24,R$5<$J24),IF(AND(R$5>=$G24,R$5<$H24),$L24,$L24+100),IF(AND(R$5>=$G24,R$5<$H24),-1,0)) -> 0 | S24: =IF(AND(S$5>=$I24,S$5<$J24),IF(AND(S$5>=$G24,S$5<$H24),$L24,$L24+100),IF(AND(S$5>=$G24,S$5<$H24),-1,0)) -> 0 | T24: =IF(AND(T$5>=$I24,T$5<$J24),IF(AND(T$5>=$G24,T$5<$H24),$L24,$L24+100),IF(AND(T$5>=$G24,T$5<$H24),-1,0)) -> 0 | ... AU24: =IF(AND(AU$5>=$I24,AU$5<$J24),IF(AND(AU$5>=$G24,AU$5<$H24),$L24,$L24+100),IF(AND(AU$5>=$G24,AU$5<$H24),-1,0)) -> 0
A25: 17 | B25: PIPING | C25: CWS | D25: Pre-Commissioning | E25: FIELD | F25: 2 | G25: =DATA!K18 -> 18 | H25: =DATA!L18 -> 20 | I25: =DATA!O18 -> 18 | J25: =DATA!P18 -> 20 | K25: =DATA!N18 -> 0 | L25: 7 | M25: =IF(AND(M$5>=$I25,M$5<$J25),IF(AND(M$5>=$G25,M$5<$H25),$L25,$L25+100),IF(AND(M$5>=$G25,M$5<$H25),-1,0)) -> 0 | N25: =IF(AND(N$5>=$I25,N$5<$J25),IF(AND(N$5>=$G25,N$5<$H25),$L25,$L25+100),IF(AND(N$5>=$G25,N$5<$H25),-1,0)) -> 0 | O25: =IF(AND(O$5>=$I25,O$5<$J25),IF(AND(O$5>=$G25,O$5<$H25),$L25,$L25+100),IF(AND(O$5>=$G25,O$5<$H25),-1,0)) -> 0 | P25: =IF(AND(P$5>=$I25,P$5<$J25),IF(AND(P$5>=$G25,P$5<$H25),$L25,$L25+100),IF(AND(P$5>=$G25,P$5<$H25),-1,0)) -> 0 | Q25: =IF(AND(Q$5>=$I25,Q$5<$J25),IF(AND(Q$5>=$G25,Q$5<$H25),$L25,$L25+100),IF(AND(Q$5>=$G25,Q$5<$H25),-1,0)) -> 0 | R25: =IF(AND(R$5>=$I25,R$5<$J25),IF(AND(R$5>=$G25,R$5<$H25),$L25,$L25+100),IF(AND(R$5>=$G25,R$5<$H25),-1,0)) -> 0 | S25: =IF(AND(S$5>=$I25,S$5<$J25),IF(AND(S$5>=$G25,S$5<$H25),$L25,$L25+100),IF(AND(S$5>=$G25,S$5<$H25),-1,0)) -> 0 | T25: =IF(AND(T$5>=$I25,T$5<$J25),IF(AND(T$5>=$G25,T$5<$H25),$L25,$L25+100),IF(AND(T$5>=$G25,T$5<$H25),-1,0)) -> 0 | ... AU25: =IF(AND(AU$5>=$I25,AU$5<$J25),IF(AND(AU$5>=$G25,AU$5<$H25),$L25,$L25+100),IF(AND(AU$5>=$G25,AU$5<$H25),-1,0)) -> 0
A26: 02. CD — 복수 계통 (Condensate) | 주요 Civil 의존: NONE
A27: 18 | B27: PIPING | C27: CD | D27: MR 발행 / 자재 발주 | E27: PROC | F27: 8 | G27: =DATA!K19 -> -14 | H27: =DATA!L19 -> -6 | I27: =DATA!O19 -> -14 | J27: =DATA!P19 -> -6 | K27: =DATA!N19 -> 0 | L27: 1 | M27: =IF(AND(M$5>=$I27,M$5<$J27),IF(AND(M$5>=$G27,M$5<$H27),$L27,$L27+100),IF(AND(M$5>=$G27,M$5<$H27),-1,0)) -> 0 | N27: =IF(AND(N$5>=$I27,N$5<$J27),IF(AND(N$5>=$G27,N$5<$H27),$L27,$L27+100),IF(AND(N$5>=$G27,N$5<$H27),-1,0)) -> 0 | O27: =IF(AND(O$5>=$I27,O$5<$J27),IF(AND(O$5>=$G27,O$5<$H27),$L27,$L27+100),IF(AND(O$5>=$G27,O$5<$H27),-1,0)) -> 0 | P27: =IF(AND(P$5>=$I27,P$5<$J27),IF(AND(P$5>=$G27,P$5<$H27),$L27,$L27+100),IF(AND(P$5>=$G27,P$5<$H27),-1,0)) -> 0 | Q27: =IF(AND(Q$5>=$I27,Q$5<$J27),IF(AND(Q$5>=$G27,Q$5<$H27),$L27,$L27+100),IF(AND(Q$5>=$G27,Q$5<$H27),-1,0)) -> 0 | R27: =IF(AND(R$5>=$I27,R$5<$J27),IF(AND(R$5>=$G27,R$5<$H27),$L27,$L27+100),IF(AND(R$5>=$G27,R$5<$H27),-1,0)) -> 0 | S27: =IF(AND(S$5>=$I27,S$5<$J27),IF(AND(S$5>=$G27,S$5<$H27),$L27,$L27+100),IF(AND(S$5>=$G27,S$5<$H27),-1,0)) -> 0 | T27: =IF(AND(T$5>=$I27,T$5<$J27),IF(AND(T$5>=$G27,T$5<$H27),$L27,$L27+100),IF(AND(T$5>=$G27,T$5<$H27),-1,0)) -> 0 | ... AU27: =IF(AND(AU$5>=$I27,AU$5<$J27),IF(AND(AU$5>=$G27,AU$5<$H27),$L27,$L27+100),IF(AND(AU$5>=$G27,AU$5<$H27),-1,0)) -> 0
A28: 19 | B28: PIPING | C28: CD | D28: 자재 입고 | E28: PROC | F28: 8 | G28: =DATA!K20 -> -4 | H28: =DATA!L20 -> 4 | I28: =DATA!O20 -> -4 | J28: =DATA!P20 -> 4 | K28: =DATA!N20 -> 0 | L28: 2 | M28: =IF(AND(M$5>=$I28,M$5<$J28),IF(AND(M$5>=$G28,M$5<$H28),$L28,$L28+100),IF(AND(M$5>=$G28,M$5<$H28),-1,0)) -> 0 | N28: =IF(AND(N$5>=$I28,N$5<$J28),IF(AND(N$5>=$G28,N$5<$H28),$L28,$L28+100),IF(AND(N$5>=$G28,N$5<$H28),-1,0)) -> 0 | O28: =IF(AND(O$5>=$I28,O$5<$J28),IF(AND(O$5>=$G28,O$5<$H28),$L28,$L28+100),IF(AND(O$5>=$G28,O$5<$H28),-1,0)) -> 0 | P28: =IF(AND(P$5>=$I28,P$5<$J28),IF(AND(P$5>=$G28,P$5<$H28),$L28,$L28+100),IF(AND(P$5>=$G28,P$5<$H28),-1,0)) -> 0 | Q28: =IF(AND(Q$5>=$I28,Q$5<$J28),IF(AND(Q$5>=$G28,Q$5<$H28),$L28,$L28+100),IF(AND(Q$5>=$G28,Q$5<$H28),-1,0)) -> 0 | R28: =IF(AND(R$5>=$I28,R$5<$J28),IF(AND(R$5>=$G28,R$5<$H28),$L28,$L28+100),IF(AND(R$5>=$G28,R$5<$H28),-1,0)) -> 0 | S28: =IF(AND(S$5>=$I28,S$5<$J28),IF(AND(S$5>=$G28,S$5<$H28),$L28,$L28+100),IF(AND(S$5>=$G28,S$5<$H28),-1,0)) -> 0 | T28: =IF(AND(T$5>=$I28,T$5<$J28),IF(AND(T$5>=$G28,T$5<$H28),$L28,$L28+100),IF(AND(T$5>=$G28,T$5<$H28),-1,0)) -> 0 | ... AU28: =IF(AND(AU$5>=$I28,AU$5<$J28),IF(AND(AU$5>=$G28,AU$5<$H28),$L28,$L28+100),IF(AND(AU$5>=$G28,AU$5<$H28),-1,0)) -> 0
A29: 20 | B29: PIPING | C29: CD | D29: Spool 제작 | E29: PROC | F29: 6 | G29: =DATA!K21 -> 0 | H29: =DATA!L21 -> 6 | I29: =DATA!O21 -> 0 | J29: =DATA!P21 -> 6 | K29: =DATA!N21 -> 0 | L29: 3 | M29: =IF(AND(M$5>=$I29,M$5<$J29),IF(AND(M$5>=$G29,M$5<$H29),$L29,$L29+100),IF(AND(M$5>=$G29,M$5<$H29),-1,0)) -> 0 | N29: =IF(AND(N$5>=$I29,N$5<$J29),IF(AND(N$5>=$G29,N$5<$H29),$L29,$L29+100),IF(AND(N$5>=$G29,N$5<$H29),-1,0)) -> 0 | O29: =IF(AND(O$5>=$I29,O$5<$J29),IF(AND(O$5>=$G29,O$5<$H29),$L29,$L29+100),IF(AND(O$5>=$G29,O$5<$H29),-1,0)) -> 0 | P29: =IF(AND(P$5>=$I29,P$5<$J29),IF(AND(P$5>=$G29,P$5<$H29),$L29,$L29+100),IF(AND(P$5>=$G29,P$5<$H29),-1,0)) -> 0 | Q29: =IF(AND(Q$5>=$I29,Q$5<$J29),IF(AND(Q$5>=$G29,Q$5<$H29),$L29,$L29+100),IF(AND(Q$5>=$G29,Q$5<$H29),-1,0)) -> 0 | R29: =IF(AND(R$5>=$I29,R$5<$J29),IF(AND(R$5>=$G29,R$5<$H29),$L29,$L29+100),IF(AND(R$5>=$G29,R$5<$H29),-1,0)) -> 0 | S29: =IF(AND(S$5>=$I29,S$5<$J29),IF(AND(S$5>=$G29,S$5<$H29),$L29,$L29+100),IF(AND(S$5>=$G29,S$5<$H29),-1,0)) -> 0 | T29: =IF(AND(T$5>=$I29,T$5<$J29),IF(AND(T$5>=$G29,T$5<$H29),$L29,$L29+100),IF(AND(T$5>=$G29,T$5<$H29),-1,0)) -> 0 | ... AU29: =IF(AND(AU$5>=$I29,AU$5<$J29),IF(AND(AU$5>=$G29,AU$5<$H29),$L29,$L29+100),IF(AND(AU$5>=$G29,AU$5<$H29),-1,0)) -> 0
A30: 21 | B30: PIPING | C30: CD | D30: 현장 배관 설치 | E30: FIELD | F30: 8 | G30: =DATA!K22 -> 4 | H30: =DATA!L22 -> 12 | I30: =DATA!O22 -> 4 | J30: =DATA!P22 -> 12 | K30: =DATA!N22 -> 0 | L30: 4 | M30: =IF(AND(M$5>=$I30,M$5<$J30),IF(AND(M$5>=$G30,M$5<$H30),$L30,$L30+100),IF(AND(M$5>=$G30,M$5<$H30),-1,0)) -> 0 | N30: =IF(AND(N$5>=$I30,N$5<$J30),IF(AND(N$5>=$G30,N$5<$H30),$L30,$L30+100),IF(AND(N$5>=$G30,N$5<$H30),-1,0)) -> 0 | O30: =IF(AND(O$5>=$I30,O$5<$J30),IF(AND(O$5>=$G30,O$5<$H30),$L30,$L30+100),IF(AND(O$5>=$G30,O$5<$H30),-1,0)) -> 0 | P30: =IF(AND(P$5>=$I30,P$5<$J30),IF(AND(P$5>=$G30,P$5<$H30),$L30,$L30+100),IF(AND(P$5>=$G30,P$5<$H30),-1,0)) -> 0 | Q30: =IF(AND(Q$5>=$I30,Q$5<$J30),IF(AND(Q$5>=$G30,Q$5<$H30),$L30,$L30+100),IF(AND(Q$5>=$G30,Q$5<$H30),-1,0)) -> 0 | R30: =IF(AND(R$5>=$I30,R$5<$J30),IF(AND(R$5>=$G30,R$5<$H30),$L30,$L30+100),IF(AND(R$5>=$G30,R$5<$H30),-1,0)) -> 0 | S30: =IF(AND(S$5>=$I30,S$5<$J30),IF(AND(S$5>=$G30,S$5<$H30),$L30,$L30+100),IF(AND(S$5>=$G30,S$5<$H30),-1,0)) -> 0 | T30: =IF(AND(T$5>=$I30,T$5<$J30),IF(AND(T$5>=$G30,T$5<$H30),$L30,$L30+100),IF(AND(T$5>=$G30,T$5<$H30),-1,0)) -> 0 | ... AU30: =IF(AND(AU$5>=$I30,AU$5<$J30),IF(AND(AU$5>=$G30,AU$5<$H30),$L30,$L30+100),IF(AND(AU$5>=$G30,AU$5<$H30),-1,0)) -> 0
A31: 22 | B31: PIPING | C31: CD | D31: Support 최종 설치/정렬 | E31: FIELD | F31: 2 | G31: =DATA!K23 -> 12 | H31: =DATA!L23 -> 14 | I31: =DATA!O23 -> 12 | J31: =DATA!P23 -> 14 | K31: =DATA!N23 -> 0 | L31: 5 | M31: =IF(AND(M$5>=$I31,M$5<$J31),IF(AND(M$5>=$G31,M$5<$H31),$L31,$L31+100),IF(AND(M$5>=$G31,M$5<$H31),-1,0)) -> 0 | N31: =IF(AND(N$5>=$I31,N$5<$J31),IF(AND(N$5>=$G31,N$5<$H31),$L31,$L31+100),IF(AND(N$5>=$G31,N$5<$H31),-1,0)) -> 0 | O31: =IF(AND(O$5>=$I31,O$5<$J31),IF(AND(O$5>=$G31,O$5<$H31),$L31,$L31+100),IF(AND(O$5>=$G31,O$5<$H31),-1,0)) -> 0 | P31: =IF(AND(P$5>=$I31,P$5<$J31),IF(AND(P$5>=$G31,P$5<$H31),$L31,$L31+100),IF(AND(P$5>=$G31,P$5<$H31),-1,0)) -> 0 | Q31: =IF(AND(Q$5>=$I31,Q$5<$J31),IF(AND(Q$5>=$G31,Q$5<$H31),$L31,$L31+100),IF(AND(Q$5>=$G31,Q$5<$H31),-1,0)) -> 0 | R31: =IF(AND(R$5>=$I31,R$5<$J31),IF(AND(R$5>=$G31,R$5<$H31),$L31,$L31+100),IF(AND(R$5>=$G31,R$5<$H31),-1,0)) -> 0 | S31: =IF(AND(S$5>=$I31,S$5<$J31),IF(AND(S$5>=$G31,S$5<$H31),$L31,$L31+100),IF(AND(S$5>=$G31,S$5<$H31),-1,0)) -> 0 | T31: =IF(AND(T$5>=$I31,T$5<$J31),IF(AND(T$5>=$G31,T$5<$H31),$L31,$L31+100),IF(AND(T$5>=$G31,T$5<$H31),-1,0)) -> 0 | ... AU31: =IF(AND(AU$5>=$I31,AU$5<$J31),IF(AND(AU$5>=$G31,AU$5<$H31),$L31,$L31+100),IF(AND(AU$5>=$G31,AU$5<$H31),-1,0)) -> 0
A32: 23 | B32: PIPING | C32: CD | D32: 수압시험 | E32: FIELD | F32: 2 | G32: =DATA!K24 -> 14 | H32: =DATA!L24 -> 16 | I32: =DATA!O24 -> 14 | J32: =DATA!P24 -> 16 | K32: =DATA!N24 -> 0 | L32: 6 | M32: =IF(AND(M$5>=$I32,M$5<$J32),IF(AND(M$5>=$G32,M$5<$H32),$L32,$L32+100),IF(AND(M$5>=$G32,M$5<$H32),-1,0)) -> 0 | N32: =IF(AND(N$5>=$I32,N$5<$J32),IF(AND(N$5>=$G32,N$5<$H32),$L32,$L32+100),IF(AND(N$5>=$G32,N$5<$H32),-1,0)) -> 0 | O32: =IF(AND(O$5>=$I32,O$5<$J32),IF(AND(O$5>=$G32,O$5<$H32),$L32,$L32+100),IF(AND(O$5>=$G32,O$5<$H32),-1,0)) -> 0 | P32: =IF(AND(P$5>=$I32,P$5<$J32),IF(AND(P$5>=$G32,P$5<$H32),$L32,$L32+100),IF(AND(P$5>=$G32,P$5<$H32),-1,0)) -> 0 | Q32: =IF(AND(Q$5>=$I32,Q$5<$J32),IF(AND(Q$5>=$G32,Q$5<$H32),$L32,$L32+100),IF(AND(Q$5>=$G32,Q$5<$H32),-1,0)) -> 0 | R32: =IF(AND(R$5>=$I32,R$5<$J32),IF(AND(R$5>=$G32,R$5<$H32),$L32,$L32+100),IF(AND(R$5>=$G32,R$5<$H32),-1,0)) -> 0 | S32: =IF(AND(S$5>=$I32,S$5<$J32),IF(AND(S$5>=$G32,S$5<$H32),$L32,$L32+100),IF(AND(S$5>=$G32,S$5<$H32),-1,0)) -> 0 | T32: =IF(AND(T$5>=$I32,T$5<$J32),IF(AND(T$5>=$G32,T$5<$H32),$L32,$L32+100),IF(AND(T$5>=$G32,T$5<$H32),-1,0)) -> 0 | ... AU32: =IF(AND(AU$5>=$I32,AU$5<$J32),IF(AND(AU$5>=$G32,AU$5<$H32),$L32,$L32+100),IF(AND(AU$5>=$G32,AU$5<$H32),-1,0)) -> 0
A33: 24 | B33: PIPING | C33: CD | D33: Pre-Commissioning | E33: FIELD | F33: 2 | G33: =DATA!K25 -> 16 | H33: =DATA!L25 -> 18 | I33: =DATA!O25 -> 16 | J33: =DATA!P25 -> 18 | K33: =DATA!N25 -> 0 | L33: 7 | M33: =IF(AND(M$5>=$I33,M$5<$J33),IF(AND(M$5>=$G33,M$5<$H33),$L33,$L33+100),IF(AND(M$5>=$G33,M$5<$H33),-1,0)) -> 0 | N33: =IF(AND(N$5>=$I33,N$5<$J33),IF(AND(N$5>=$G33,N$5<$H33),$L33,$L33+100),IF(AND(N$5>=$G33,N$5<$H33),-1,0)) -> 0 | O33: =IF(AND(O$5>=$I33,O$5<$J33),IF(AND(O$5>=$G33,O$5<$H33),$L33,$L33+100),IF(AND(O$5>=$G33,O$5<$H33),-1,0)) -> 0 | P33: =IF(AND(P$5>=$I33,P$5<$J33),IF(AND(P$5>=$G33,P$5<$H33),$L33,$L33+100),IF(AND(P$5>=$G33,P$5<$H33),-1,0)) -> 0 | Q33: =IF(AND(Q$5>=$I33,Q$5<$J33),IF(AND(Q$5>=$G33,Q$5<$H33),$L33,$L33+100),IF(AND(Q$5>=$G33,Q$5<$H33),-1,0)) -> 0 | R33: =IF(AND(R$5>=$I33,R$5<$J33),IF(AND(R$5>=$G33,R$5<$H33),$L33,$L33+100),IF(AND(R$5>=$G33,R$5<$H33),-1,0)) -> 0 | S33: =IF(AND(S$5>=$I33,S$5<$J33),IF(AND(S$5>=$G33,S$5<$H33),$L33,$L33+100),IF(AND(S$5>=$G33,S$5<$H33),-1,0)) -> 0 | T33: =IF(AND(T$5>=$I33,T$5<$J33),IF(AND(T$5>=$G33,T$5<$H33),$L33,$L33+100),IF(AND(T$5>=$G33,T$5<$H33),-1,0)) -> 0 | ... AU33: =IF(AND(AU$5>=$I33,AU$5<$J33),IF(AND(AU$5>=$G33,AU$5<$H33),$L33,$L33+100),IF(AND(AU$5>=$G33,AU$5<$H33),-1,0)) -> 0
A34: 03. FW — 급수 계통 (Feed Water) | 주요 Civil 의존: NONE
A35: 25 | B35: PIPING | C35: FW | D35: MR 발행 / 자재 발주 | E35: PROC | F35: 8 | G35: =DATA!K26 -> -14 | H35: =DATA!L26 -> -6 | I35: =DATA!O26 -> -14 | J35: =DATA!P26 -> -6 | K35: =DATA!N26 -> 0 | L35: 1 | M35: =IF(AND(M$5>=$I35,M$5<$J35),IF(AND(M$5>=$G35,M$5<$H35),$L35,$L35+100),IF(AND(M$5>=$G35,M$5<$H35),-1,0)) -> 0 | N35: =IF(AND(N$5>=$I35,N$5<$J35),IF(AND(N$5>=$G35,N$5<$H35),$L35,$L35+100),IF(AND(N$5>=$G35,N$5<$H35),-1,0)) -> 0 | O35: =IF(AND(O$5>=$I35,O$5<$J35),IF(AND(O$5>=$G35,O$5<$H35),$L35,$L35+100),IF(AND(O$5>=$G35,O$5<$H35),-1,0)) -> 0 | P35: =IF(AND(P$5>=$I35,P$5<$J35),IF(AND(P$5>=$G35,P$5<$H35),$L35,$L35+100),IF(AND(P$5>=$G35,P$5<$H35),-1,0)) -> 0 | Q35: =IF(AND(Q$5>=$I35,Q$5<$J35),IF(AND(Q$5>=$G35,Q$5<$H35),$L35,$L35+100),IF(AND(Q$5>=$G35,Q$5<$H35),-1,0)) -> 0 | R35: =IF(AND(R$5>=$I35,R$5<$J35),IF(AND(R$5>=$G35,R$5<$H35),$L35,$L35+100),IF(AND(R$5>=$G35,R$5<$H35),-1,0)) -> 0 | S35: =IF(AND(S$5>=$I35,S$5<$J35),IF(AND(S$5>=$G35,S$5<$H35),$L35,$L35+100),IF(AND(S$5>=$G35,S$5<$H35),-1,0)) -> 0 | T35: =IF(AND(T$5>=$I35,T$5<$J35),IF(AND(T$5>=$G35,T$5<$H35),$L35,$L35+100),IF(AND(T$5>=$G35,T$5<$H35),-1,0)) -> 0 | ... AU35: =IF(AND(AU$5>=$I35,AU$5<$J35),IF(AND(AU$5>=$G35,AU$5<$H35),$L35,$L35+100),IF(AND(AU$5>=$G35,AU$5<$H35),-1,0)) -> 0
A36: 26 | B36: PIPING | C36: FW | D36: 자재 입고 (고압배관) | E36: PROC | F36: 8 | G36: =DATA!K27 -> -4 | H36: =DATA!L27 -> 4 | I36: =DATA!O27 -> -4 | J36: =DATA!P27 -> 4 | K36: =DATA!N27 -> 0 | L36: 2 | M36: =IF(AND(M$5>=$I36,M$5<$J36),IF(AND(M$5>=$G36,M$5<$H36),$L36,$L36+100),IF(AND(M$5>=$G36,M$5<$H36),-1,0)) -> 0 | N36: =IF(AND(N$5>=$I36,N$5<$J36),IF(AND(N$5>=$G36,N$5<$H36),$L36,$L36+100),IF(AND(N$5>=$G36,N$5<$H36),-1,0)) -> 0 | O36: =IF(AND(O$5>=$I36,O$5<$J36),IF(AND(O$5>=$G36,O$5<$H36),$L36,$L36+100),IF(AND(O$5>=$G36,O$5<$H36),-1,0)) -> 0 | P36: =IF(AND(P$5>=$I36,P$5<$J36),IF(AND(P$5>=$G36,P$5<$H36),$L36,$L36+100),IF(AND(P$5>=$G36,P$5<$H36),-1,0)) -> 0 | Q36: =IF(AND(Q$5>=$I36,Q$5<$J36),IF(AND(Q$5>=$G36,Q$5<$H36),$L36,$L36+100),IF(AND(Q$5>=$G36,Q$5<$H36),-1,0)) -> 0 | R36: =IF(AND(R$5>=$I36,R$5<$J36),IF(AND(R$5>=$G36,R$5<$H36),$L36,$L36+100),IF(AND(R$5>=$G36,R$5<$H36),-1,0)) -> 0 | S36: =IF(AND(S$5>=$I36,S$5<$J36),IF(AND(S$5>=$G36,S$5<$H36),$L36,$L36+100),IF(AND(S$5>=$G36,S$5<$H36),-1,0)) -> 0 | T36: =IF(AND(T$5>=$I36,T$5<$J36),IF(AND(T$5>=$G36,T$5<$H36),$L36,$L36+100),IF(AND(T$5>=$G36,T$5<$H36),-1,0)) -> 0 | ... AU36: =IF(AND(AU$5>=$I36,AU$5<$J36),IF(AND(AU$5>=$G36,AU$5<$H36),$L36,$L36+100),IF(AND(AU$5>=$G36,AU$5<$H36),-1,0)) -> 0
A37: 27 | B37: PIPING | C37: FW | D37: Spool 제작 (고압) | E37: PROC | F37: 6 | G37: =DATA!K28 -> -2 | H37: =DATA!L28 -> 4 | I37: =DATA!O28 -> -2 | J37: =DATA!P28 -> 4 | K37: =DATA!N28 -> 0 | L37: 3 | M37: =IF(AND(M$5>=$I37,M$5<$J37),IF(AND(M$5>=$G37,M$5<$H37),$L37,$L37+100),IF(AND(M$5>=$G37,M$5<$H37),-1,0)) -> 0 | N37: =IF(AND(N$5>=$I37,N$5<$J37),IF(AND(N$5>=$G37,N$5<$H37),$L37,$L37+100),IF(AND(N$5>=$G37,N$5<$H37),-1,0)) -> 0 | O37: =IF(AND(O$5>=$I37,O$5<$J37),IF(AND(O$5>=$G37,O$5<$H37),$L37,$L37+100),IF(AND(O$5>=$G37,O$5<$H37),-1,0)) -> 0 | P37: =IF(AND(P$5>=$I37,P$5<$J37),IF(AND(P$5>=$G37,P$5<$H37),$L37,$L37+100),IF(AND(P$5>=$G37,P$5<$H37),-1,0)) -> 0 | Q37: =IF(AND(Q$5>=$I37,Q$5<$J37),IF(AND(Q$5>=$G37,Q$5<$H37),$L37,$L37+100),IF(AND(Q$5>=$G37,Q$5<$H37),-1,0)) -> 0 | R37: =IF(AND(R$5>=$I37,R$5<$J37),IF(AND(R$5>=$G37,R$5<$H37),$L37,$L37+100),IF(AND(R$5>=$G37,R$5<$H37),-1,0)) -> 0 | S37: =IF(AND(S$5>=$I37,S$5<$J37),IF(AND(S$5>=$G37,S$5<$H37),$L37,$L37+100),IF(AND(S$5>=$G37,S$5<$H37),-1,0)) -> 0 | T37: =IF(AND(T$5>=$I37,T$5<$J37),IF(AND(T$5>=$G37,T$5<$H37),$L37,$L37+100),IF(AND(T$5>=$G37,T$5<$H37),-1,0)) -> 0 | ... AU37: =IF(AND(AU$5>=$I37,AU$5<$J37),IF(AND(AU$5>=$G37,AU$5<$H37),$L37,$L37+100),IF(AND(AU$5>=$G37,AU$5<$H37),-1,0)) -> 0
A38: 28 | B38: PIPING | C38: FW | D38: 현장 배관 설치 | E38: FIELD | F38: 8 | G38: =DATA!K29 -> 4 | H38: =DATA!L29 -> 12 | I38: =DATA!O29 -> 4 | J38: =DATA!P29 -> 12 | K38: =DATA!N29 -> 0 | L38: 4 | M38: =IF(AND(M$5>=$I38,M$5<$J38),IF(AND(M$5>=$G38,M$5<$H38),$L38,$L38+100),IF(AND(M$5>=$G38,M$5<$H38),-1,0)) -> 0 | N38: =IF(AND(N$5>=$I38,N$5<$J38),IF(AND(N$5>=$G38,N$5<$H38),$L38,$L38+100),IF(AND(N$5>=$G38,N$5<$H38),-1,0)) -> 0 | O38: =IF(AND(O$5>=$I38,O$5<$J38),IF(AND(O$5>=$G38,O$5<$H38),$L38,$L38+100),IF(AND(O$5>=$G38,O$5<$H38),-1,0)) -> 0 | P38: =IF(AND(P$5>=$I38,P$5<$J38),IF(AND(P$5>=$G38,P$5<$H38),$L38,$L38+100),IF(AND(P$5>=$G38,P$5<$H38),-1,0)) -> 0 | Q38: =IF(AND(Q$5>=$I38,Q$5<$J38),IF(AND(Q$5>=$G38,Q$5<$H38),$L38,$L38+100),IF(AND(Q$5>=$G38,Q$5<$H38),-1,0)) -> 0 | R38: =IF(AND(R$5>=$I38,R$5<$J38),IF(AND(R$5>=$G38,R$5<$H38),$L38,$L38+100),IF(AND(R$5>=$G38,R$5<$H38),-1,0)) -> 0 | S38: =IF(AND(S$5>=$I38,S$5<$J38),IF(AND(S$5>=$G38,S$5<$H38),$L38,$L38+100),IF(AND(S$5>=$G38,S$5<$H38),-1,0)) -> 0 | T38: =IF(AND(T$5>=$I38,T$5<$J38),IF(AND(T$5>=$G38,T$5<$H38),$L38,$L38+100),IF(AND(T$5>=$G38,T$5<$H38),-1,0)) -> 0 | ... AU38: =IF(AND(AU$5>=$I38,AU$5<$J38),IF(AND(AU$5>=$G38,AU$5<$H38),$L38,$L38+100),IF(AND(AU$5>=$G38,AU$5<$H38),-1,0)) -> 0
A39: 29 | B39: PIPING | C39: FW | D39: Support 최종 설치/정렬 | E39: FIELD | F39: 2 | G39: =DATA!K30 -> 12 | H39: =DATA!L30 -> 14 | I39: =DATA!O30 -> 12 | J39: =DATA!P30 -> 14 | K39: =DATA!N30 -> 0 | L39: 5 | M39: =IF(AND(M$5>=$I39,M$5<$J39),IF(AND(M$5>=$G39,M$5<$H39),$L39,$L39+100),IF(AND(M$5>=$G39,M$5<$H39),-1,0)) -> 0 | N39: =IF(AND(N$5>=$I39,N$5<$J39),IF(AND(N$5>=$G39,N$5<$H39),$L39,$L39+100),IF(AND(N$5>=$G39,N$5<$H39),-1,0)) -> 0 | O39: =IF(AND(O$5>=$I39,O$5<$J39),IF(AND(O$5>=$G39,O$5<$H39),$L39,$L39+100),IF(AND(O$5>=$G39,O$5<$H39),-1,0)) -> 0 | P39: =IF(AND(P$5>=$I39,P$5<$J39),IF(AND(P$5>=$G39,P$5<$H39),$L39,$L39+100),IF(AND(P$5>=$G39,P$5<$H39),-1,0)) -> 0 | Q39: =IF(AND(Q$5>=$I39,Q$5<$J39),IF(AND(Q$5>=$G39,Q$5<$H39),$L39,$L39+100),IF(AND(Q$5>=$G39,Q$5<$H39),-1,0)) -> 0 | R39: =IF(AND(R$5>=$I39,R$5<$J39),IF(AND(R$5>=$G39,R$5<$H39),$L39,$L39+100),IF(AND(R$5>=$G39,R$5<$H39),-1,0)) -> 0 | S39: =IF(AND(S$5>=$I39,S$5<$J39),IF(AND(S$5>=$G39,S$5<$H39),$L39,$L39+100),IF(AND(S$5>=$G39,S$5<$H39),-1,0)) -> 0 | T39: =IF(AND(T$5>=$I39,T$5<$J39),IF(AND(T$5>=$G39,T$5<$H39),$L39,$L39+100),IF(AND(T$5>=$G39,T$5<$H39),-1,0)) -> 0 | ... AU39: =IF(AND(AU$5>=$I39,AU$5<$J39),IF(AND(AU$5>=$G39,AU$5<$H39),$L39,$L39+100),IF(AND(AU$5>=$G39,AU$5<$H39),-1,0)) -> 0
A40: 30 | B40: PIPING | C40: FW | D40: 수압시험 | E40: FIELD | F40: 2 | G40: =DATA!K31 -> 14 | H40: =DATA!L31 -> 16 | I40: =DATA!O31 -> 14 | J40: =DATA!P31 -> 16 | K40: =DATA!N31 -> 0 | L40: 6 | M40: =IF(AND(M$5>=$I40,M$5<$J40),IF(AND(M$5>=$G40,M$5<$H40),$L40,$L40+100),IF(AND(M$5>=$G40,M$5<$H40),-1,0)) -> 0 | N40: =IF(AND(N$5>=$I40,N$5<$J40),IF(AND(N$5>=$G40,N$5<$H40),$L40,$L40+100),IF(AND(N$5>=$G40,N$5<$H40),-1,0)) -> 0 | O40: =IF(AND(O$5>=$I40,O$5<$J40),IF(AND(O$5>=$G40,O$5<$H40),$L40,$L40+100),IF(AND(O$5>=$G40,O$5<$H40),-1,0)) -> 0 | P40: =IF(AND(P$5>=$I40,P$5<$J40),IF(AND(P$5>=$G40,P$5<$H40),$L40,$L40+100),IF(AND(P$5>=$G40,P$5<$H40),-1,0)) -> 0 | Q40: =IF(AND(Q$5>=$I40,Q$5<$J40),IF(AND(Q$5>=$G40,Q$5<$H40),$L40,$L40+100),IF(AND(Q$5>=$G40,Q$5<$H40),-1,0)) -> 0 | R40: =IF(AND(R$5>=$I40,R$5<$J40),IF(AND(R$5>=$G40,R$5<$H40),$L40,$L40+100),IF(AND(R$5>=$G40,R$5<$H40),-1,0)) -> 0 | S40: =IF(AND(S$5>=$I40,S$5<$J40),IF(AND(S$5>=$G40,S$5<$H40),$L40,$L40+100),IF(AND(S$5>=$G40,S$5<$H40),-1,0)) -> 0 | T40: =IF(AND(T$5>=$I40,T$5<$J40),IF(AND(T$5>=$G40,T$5<$H40),$L40,$L40+100),IF(AND(T$5>=$G40,T$5<$H40),-1,0)) -> 0 | ... AU40: =IF(AND(AU$5>=$I40,AU$5<$J40),IF(AND(AU$5>=$G40,AU$5<$H40),$L40,$L40+100),IF(AND(AU$5>=$G40,AU$5<$H40),-1,0)) -> 0
...
